Workbook

Sheet Recordatorios Programados
A1: Panel visual de recordatorios programados por casa
A2: MODO PRUEBA: la columna Hora permite seleccionar cualquier minuto del dÃ­a. Cuando termines, ejecuta CambiarHorasModoHorasFijas.ps1 para volver a horas fijas.
A4: Casa / Grupo exacto | B4: Categoría | C4: Lun | D4: Mar | E4: Mié | F4: Jue | G4: Vie | H4: Sáb | I4: Dom | J4: Hora | K4: Activo | L4: Enviar manual | M4: Estado | N4: Último envío | O4: Próximo envío | P4: Mensaje | Q4: Notas
A5: CASA / GRUPO: ACME Residence 001
A6: ACME Residence 001 | B6: Limpieza y orden | C6: FALSE | D6: FALSE | E6: FALSE | F6: FALSE | G6: FALSE | H6: FALSE | I6: FALSE | K6: SI | L6: NO | M6: PENDING | O6: {=_xlfn.LET(_xlpm.activo,K6,_xlpm.horaTxt,J6,_xlpm.base,TODAY(),_xlpm.fechas,_xlpm.base+_xlfn.SEQUENCE(180,,0),_xlpm.hora,IF(ISNUMBER(_xlpm.horaTxt),_xlpm.horaTxt,IFERROR(TIMEVALUE(SUBSTITUTE(_xlpm.horaTxt," hrs","")),TIME(9,0,0))),_xlpm.dias,(C6*(WEEKDAY(_xlpm.fechas,2)=1))+(D6*(WEEKDAY(_xlpm.fechas,2)=2))+(E6*(WEEKDAY(_xlpm.fechas,2)=3))+(F6*(WEEKDAY(_xlpm.fechas,2)=4))+(G6*(WEEKDAY(_xlpm.fechas,2)=5))+(H6*(WEEKDAY(_xlpm.fechas,2)=6))+(I6*(WEEKDAY(_xlpm.fechas,2)=7)),_xlpm.validas,_xlfn._xlws.FILTER(_xlpm.fechas,(_xlpm.dias>0)*((_xlpm.fechas+_xlpm.hora)>=(NOW()-TIME(0,3,0)))),_xlpm.prox,_xlfn.TAKE(_xlpm.validas,4),IF(_xlpm.activo<>"SI","Inactivo",IF(SUMPRODUCT(--C6:I6)=0,"Manual / cuando aplique",_xlfn.TEXTJOIN(CHAR(10),TRUE,_xlfn.MAP(_xlpm.prox,_xlfn.LAMBDA(_xlpm.f,CHOOSE(WEEKDAY(_xlpm.f),"domingo","lunes","martes","miércoles","jueves","viernes","sábado")&" "&TEXT(_xlpm.f,"dd")&"/"&CHOOSE(MONTH(_xlpm.f),"Ene","Feb","Mar","Abr","May","Jun","Jul","Ago","Sep","Oct","Nov","Dic")&"/"&TEXT(_xlpm.f,"yyyy")&" "&TEXT(_xlpm.hora,"hh:mm")&" hrs"))))))} -> Manual / cuando aplique | P6: Buenos días chicos,_x000D_ _x000D_ Como recordatorio, les pido de su amable apoyo para:_x000D_ _x000D_ * Lavar, secar y guardar los trastes que utilicen._x000D_ * Barrer la cocina y dejarla limpia para que la siguiente persona la encuentre en las mismas condiciones._x000D_ * Apagar todas las luces que no estén utilizando._x000D_ * Colocar las sillas del comedor en su lugar después de usarlas._x000D_ _x000D_ Muchas gracias por su colaboración para mantener la casa limpia y ordenada.
A7: ACME Residence 001 | B7: Lavandería - horario | C7: TRUE | D7: FALSE | E7: FALSE | F7: TRUE | G7: FALSE | H7: FALSE | I7: FALSE | J7: 19:00 hrs | K7: SI | L7: NO | M7: PENDING | O7: {=_xlfn.LET(_xlpm.activo,K7,_xlpm.horaTxt,J7,_xlpm.base,TODAY(),_xlpm.fechas,_xlpm.base+_xlfn.SEQUENCE(180,,0),_xlpm.hora,IF(ISNUMBER(_xlpm.horaTxt),_xlpm.horaTxt,IFERROR(TIMEVALUE(SUBSTITUTE(_xlpm.horaTxt," hrs","")),TIME(9,0,0))),_xlpm.dias,(C7*(WEEKDAY(_xlpm.fechas,2)=1))+(D7*(WEEKDAY(_xlpm.fechas,2)=2))+(E7*(WEEKDAY(_xlpm.fechas,2)=3))+(F7*(WEEKDAY(_xlpm.fechas,2)=4))+(G7*(WEEKDAY(_xlpm.fechas,2)=5))+(H7*(WEEKDAY(_xlpm.fechas,2)=6))+(I7*(WEEKDAY(_xlpm.fechas,2)=7)),_xlpm.validas,_xlfn._xlws.FILTER(_xlpm.fechas,(_xlpm.dias>0)*((_xlpm.fechas+_xlpm.hora)>=(NOW()-TIME(0,3,0)))),_xlpm.prox,_xlfn.TAKE(_xlpm.validas,4),IF(_xlpm.activo<>"SI","Inactivo",IF(SUMPRODUCT(--C7:I7)=0,"Manual / cuando aplique",_xlfn.TEXTJOIN(CHAR(10),TRUE,_xlfn.MAP(_xlpm.prox,_xlfn.LAMBDA(_xlpm.f,CHOOSE(WEEKDAY(_xlpm.f),"domingo","lunes","martes","miércoles","jueves","viernes","sábado")&" "&TEXT(_xlpm.f,"dd")&"/"&CHOOSE(MONTH(_xlpm.f),"Ene","Feb","Mar","Abr","May","Jun","Jul","Ago","Sep","Oct","Nov","Dic")&"/"&TEXT(_xlpm.f,"yyyy")&" "&TEXT(_xlpm.hora,"hh:mm")&" hrs"))))))} -> lunes 13/Jul/2026 19:00 hrs jueves 16/Jul/2026 19:00 hrs lunes 20/Jul/2026 19:00 hrs jueves 23/Jul/2026 19:00 hrs | P7: Buenas tardes, chicos._x000D_ _x000D_ Solo para confirmarles que el horario de lavado ya está disponible. Pueden utilizar la lavandería de 7:00 p. m. a 10:30 p. m._x000D_ _x000D_ Gracias.
A8: ACME Residence 001 | B8: Lavandería - filtro secadora | C8: TRUE | D8: FALSE | E8: FALSE | F8: TRUE | G8: FALSE | H8: FALSE | I8: FALSE | J8: 20:00 hrs | K8: SI | L8: NO | M8: PENDING | O8: {=_xlfn.LET(_xlpm.activo,K8,_xlpm.horaTxt,J8,_xlpm.base,TODAY(),_xlpm.fechas,_xlpm.base+_xlfn.SEQUENCE(180,,0),_xlpm.hora,IF(ISNUMBER(_xlpm.horaTxt),_xlpm.horaTxt,IFERROR(TIMEVALUE(SUBSTITUTE(_xlpm.horaTxt," hrs","")),TIME(9,0,0))),_xlpm.dias,(C8*(WEEKDAY(_xlpm.fechas,2)=1))+(D8*(WEEKDAY(_xlpm.fechas,2)=2))+(E8*(WEEKDAY(_xlpm.fechas,2)=3))+(F8*(WEEKDAY(_xlpm.fechas,2)=4))+(G8*(WEEKDAY(_xlpm.fechas,2)=5))+(H8*(WEEKDAY(_xlpm.fechas,2)=6))+(I8*(WEEKDAY(_xlpm.fechas,2)=7)),_xlpm.validas,_xlfn._xlws.FILTER(_xlpm.fechas,(_xlpm.dias>0)*((_xlpm.fechas+_xlpm.hora)>=(NOW()-TIME(0,3,0)))),_xlpm.prox,_xlfn.TAKE(_xlpm.validas,4),IF(_xlpm.activo<>"SI","Inactivo",IF(SUMPRODUCT(--C8:I8)=0,"Manual / cuando aplique",_xlfn.TEXTJOIN(CHAR(10),TRUE,_xlfn.MAP(_xlpm.prox,_xlfn.LAMBDA(_xlpm.f,CHOOSE(WEEKDAY(_xlpm.f),"domingo","lunes","martes","miércoles","jueves","viernes","sábado")&" "&TEXT(_xlpm.f,"dd")&"/"&CHOOSE(MONTH(_xlpm.f),"Ene","Feb","Mar","Abr","May","Jun","Jul","Ago","Sep","Oct","Nov","Dic")&"/"&TEXT(_xlpm.f,"yyyy")&" "&TEXT(_xlpm.hora,"hh:mm")&" hrs"))))))} -> lunes 13/Jul/2026 20:00 hrs jueves 16/Jul/2026 20:00 hrs lunes 20/Jul/2026 20:00 hrs jueves 23/Jul/2026 20:00 hrs | P8: Como recordatorio, les pido que después de utilizar la secadora limpien el filtro. Es importante cuidarla para mantenerla en buen funcionamiento y evitar daños._x000D_ _x000D_ Gracias por su apoyo.
A9: ACME Residence 001 | B9: Estufa y luces | C9: FALSE | D9: TRUE | E9: FALSE | F9: TRUE | G9: FALSE | H9: FALSE | I9: FALSE | J9: 21:00 hrs | K9: SI | L9: NO | M9: PENDING | O9: {=_xlfn.LET(_xlpm.activo,K9,_xlpm.horaTxt,J9,_xlpm.base,TODAY(),_xlpm.fechas,_xlpm.base+_xlfn.SEQUENCE(180,,0),_xlpm.hora,IF(ISNUMBER(_xlpm.horaTxt),_xlpm.horaTxt,IFERROR(TIMEVALUE(SUBSTITUTE(_xlpm.horaTxt," hrs","")),TIME(9,0,0))),_xlpm.dias,(C9*(WEEKDAY(_xlpm.fechas,2)=1))+(D9*(WEEKDAY(_xlpm.fechas,2)=2))+(E9*(WEEKDAY(_xlpm.fechas,2)=3))+(F9*(WEEKDAY(_xlpm.fechas,2)=4))+(G9*(WEEKDAY(_xlpm.fechas,2)=5))+(H9*(WEEKDAY(_xlpm.fechas,2)=6))+(I9*(WEEKDAY(_xlpm.fechas,2)=7)),_xlpm.validas,_xlfn._xlws.FILTER(_xlpm.fechas,(_xlpm.dias>0)*((_xlpm.fechas+_xlpm.hora)>=(NOW()-TIME(0,3,0)))),_xlpm.prox,_xlfn.TAKE(_xlpm.validas,4),IF(_xlpm.activo<>"SI","Inactivo",IF(SUMPRODUCT(--C9:I9)=0,"Manual / cuando aplique",_xlfn.TEXTJOIN(CHAR(10),TRUE,_xlfn.MAP(_xlpm.prox,_xlfn.LAMBDA(_xlpm.f,CHOOSE(WEEKDAY(_xlpm.f),"domingo","lunes","martes","miércoles","jueves","viernes","sábado")&" "&TEXT(_xlpm.f,"dd")&"/"&CHOOSE(MONTH(_xlpm.f),"Ene","Feb","Mar","Abr","May","Jun","Jul","Ago","Sep","Oct","Nov","Dic")&"/"&TEXT(_xlpm.f,"yyyy")&" "&TEXT(_xlpm.hora,"hh:mm")&" hrs"))))))} -> martes 14/Jul/2026 21:00 hrs jueves 16/Jul/2026 21:00 hrs martes 21/Jul/2026 21:00 hrs jueves 23/Jul/2026 21:00 hrs | P9: Buenas noches a todos, chicos._x000D_ _x000D_ Como recordatorio, les pido que antes de dormir verifiquen que la estufa esté completamente apagada para evitar accidentes. Asimismo, favor de apagar todas las luces que no se estén utilizando._x000D_ _x000D_ Gracias por su apoyo y que tengan una excelente noche.
A10: ACME Residence 001 | B10: Ruido fin de semana | C10: FALSE | D10: FALSE | E10: FALSE | F10: FALSE | G10: FALSE | H10: TRUE | I10: FALSE | J10: 21:00 hrs | K10: SI | L10: NO | M10: PENDING | O10: {=_xlfn.LET(_xlpm.activo,K10,_xlpm.horaTxt,J10,_xlpm.base,TODAY(),_xlpm.fechas,_xlpm.base+_xlfn.SEQUENCE(180,,0),_xlpm.hora,IF(ISNUMBER(_xlpm.horaTxt),_xlpm.horaTxt,IFERROR(TIMEVALUE(SUBSTITUTE(_xlpm.horaTxt," hrs","")),TIME(9,0,0))),_xlpm.dias,(C10*(WEEKDAY(_xlpm.fechas,2)=1))+(D10*(WEEKDAY(_xlpm.fechas,2)=2))+(E10*(WEEKDAY(_xlpm.fechas,2)=3))+(F10*(WEEKDAY(_xlpm.fechas,2)=4))+(G10*(WEEKDAY(_xlpm.fechas,2)=5))+(H10*(WEEKDAY(_xlpm.fechas,2)=6))+(I10*(WEEKDAY(_xlpm.fechas,2)=7)),_xlpm.validas,_xlfn._xlws.FILTER(_xlpm.fechas,(_xlpm.dias>0)*((_xlpm.fechas+_xlpm.hora)>=(NOW()-TIME(0,3,0)))),_xlpm.prox,_xlfn.TAKE(_xlpm.validas,4),IF(_xlpm.activo<>"SI","Inactivo",IF(SUMPRODUCT(--C10:I10)=0,"Manual / cuando aplique",_xlfn.TEXTJOIN(CHAR(10),TRUE,_xlfn.MAP(_xlpm.prox,_xlfn.LAMBDA(_xlpm.f,CHOOSE(WEEKDAY(_xlpm.f),"domingo","lunes","martes","miércoles","jueves","viernes","sábado")&" "&TEXT(_xlpm.f,"dd")&"/"&CHOOSE(MONTH(_xlpm.f),"Ene","Feb","Mar","Abr","May","Jun","Jul","Ago","Sep","Oct","Nov","Dic")&"/"&TEXT(_xlpm.f,"yyyy")&" "&TEXT(_xlpm.hora,"hh:mm")&" hrs"))))))} -> sábado 11/Jul/2026 21:00 hrs sábado 18/Jul/2026 21:00 hrs sábado 25/Jul/2026 21:00 hrs sábado 01/Ago/2026 21:00 hrs | P10: Buenas noches a todos, chicos._x000D_ _x000D_ Solo como recordatorio, al ser fin de semana les pedimos de la manera más amable que moderen el ruido. Sabemos que muchos aprovechan estos días, pero también hay personas que necesitan descansar después de una semana de trabajo._x000D_ _x000D_ Seamos considerados con los demás y ayudemos a mantener un ambiente tranquilo para todos._x000D_ _x000D_ Muchas gracias por su apoyo. ¡Que tengan una excelente noche!
A11: CASA / GRUPO: ACME Residence 002
A12: ACME Residence 002 | B12: Limpieza y orden | C12: FALSE | D12: FALSE | E12: FALSE | F12: FALSE | G12: FALSE | H12: FALSE | I12: FALSE | K12: SI | L12: NO | M12: PENDING | O12: {=_xlfn.LET(_xlpm.activo,K12,_xlpm.horaTxt,J12,_xlpm.base,TODAY(),_xlpm.fechas,_xlpm.base+_xlfn.SEQUENCE(180,,0),_xlpm.hora,IF(ISNUMBER(_xlpm.horaTxt),_xlpm.horaTxt,IFERROR(TIMEVALUE(SUBSTITUTE(_xlpm.horaTxt," hrs","")),TIME(9,0,0))),_xlpm.dias,(C12*(WEEKDAY(_xlpm.fechas,2)=1))+(D12*(WEEKDAY(_xlpm.fechas,2)=2))+(E12*(WEEKDAY(_xlpm.fechas,2)=3))+(F12*(WEEKDAY(_xlpm.fechas,2)=4))+(G12*(WEEKDAY(_xlpm.fechas,2)=5))+(H12*(WEEKDAY(_xlpm.fechas,2)=6))+(I12*(WEEKDAY(_xlpm.fechas,2)=7)),_xlpm.validas,_xlfn._xlws.FILTER(_xlpm.fechas,(_xlpm.dias>0)*((_xlpm.fechas+_xlpm.hora)>=(NOW()-TIME(0,3,0)))),_xlpm.prox,_xlfn.TAKE(_xlpm.validas,4),IF(_xlpm.activo<>"SI","Inactivo",IF(SUMPRODUCT(--C12:I12)=0,"Manual / cuando aplique",_xlfn.TEXTJOIN(CHAR(10),TRUE,_xlfn.MAP(_xlpm.prox,_xlfn.LAMBDA(_xlpm.f,CHOOSE(WEEKDAY(_xlpm.f),"domingo","lunes","martes","miércoles","jueves","viernes","sábado")&" "&TEXT(_xlpm.f,"dd")&"/"&CHOOSE(MONTH(_xlpm.f),"Ene","Feb","Mar","Abr","May","Jun","Jul","Ago","Sep","Oct","Nov","Dic")&"/"&TEXT(_xlpm.f,"yyyy")&" "&TEXT(_xlpm.hora,"hh:mm")&" hrs"))))))} -> Manual / cuando aplique | P12: Buenos días chicos,_x000D_ _x000D_ Como recordatorio, les pido de su amable apoyo para:_x000D_ _x000D_ * Lavar, secar y guardar los trastes que utilicen._x000D_ * Barrer la cocina y dejarla limpia para que la siguiente persona la encuentre en las mismas condiciones._x000D_ * Apagar todas las luces que no estén utilizando._x000D_ * Colocar las sillas del comedor en su lugar después de usarlas._x000D_ _x000D_ Muchas gracias por su colaboración para mantener la casa limpia y ordenada.
A13: ACME Residence 002 | B13: Lavandería - horario | C13: TRUE | D13: FALSE | E13: FALSE | F13: TRUE | G13: FALSE | H13: FALSE | I13: FALSE | J13: 19:00 hrs | K13: SI | L13: NO | M13: PENDING | O13: {=_xlfn.LET(_xlpm.activo,K13,_xlpm.horaTxt,J13,_xlpm.base,TODAY(),_xlpm.fechas,_xlpm.base+_xlfn.SEQUENCE(180,,0),_xlpm.hora,IF(ISNUMBER(_xlpm.horaTxt),_xlpm.horaTxt,IFERROR(TIMEVALUE(SUBSTITUTE(_xlpm.horaTxt," hrs","")),TIME(9,0,0))),_xlpm.dias,(C13*(WEEKDAY(_xlpm.fechas,2)=1))+(D13*(WEEKDAY(_xlpm.fechas,2)=2))+(E13*(WEEKDAY(_xlpm.fechas,2)=3))+(F13*(WEEKDAY(_xlpm.fechas,2)=4))+(G13*(WEEKDAY(_xlpm.fechas,2)=5))+(H13*(WEEKDAY(_xlpm.fechas,2)=6))+(I13*(WEEKDAY(_xlpm.fechas,2)=7)),_xlpm.validas,_xlfn._xlws.FILTER(_xlpm.fechas,(_xlpm.dias>0)*((_xlpm.fechas+_xlpm.hora)>=(NOW()-TIME(0,3,0)))),_xlpm.prox,_xlfn.TAKE(_xlpm.validas,4),IF(_xlpm.activo<>"SI","Inactivo",IF(SUMPRODUCT(--C13:I13)=0,"Manual / cuando aplique",_xlfn.TEXTJOIN(CHAR(10),TRUE,_xlfn.MAP(_xlpm.prox,_xlfn.LAMBDA(_xlpm.f,CHOOSE(WEEKDAY(_xlpm.f),"domingo","lunes","martes","miércoles","jueves","viernes","sábado")&" "&TEXT(_xlpm.f,"dd")&"/"&CHOOSE(MONTH(_xlpm.f),"Ene","Feb","Mar","Abr","May","Jun","Jul","Ago","Sep","Oct","Nov","Dic")&"/"&TEXT(_xlpm.f,"yyyy")&" "&TEXT(_xlpm.hora,"hh:mm")&" hrs"))))))} -> lunes 13/Jul/2026 19:00 hrs jueves 16/Jul/2026 19:00 hrs lunes 20/Jul/2026 19:00 hrs jueves 23/Jul/2026 19:00 hrs | P13: Buenas tardes, chicos._x000D_ _x000D_ Solo para confirmarles que el horario de lavado ya está disponible. Pueden utilizar la lavandería de 7:00 p. m. a 10:30 p. m._x000D_ _x000D_ Gracias.
A14: ACME Residence 002 | B14: Lavandería - filtro secadora | C14: TRUE | D14: FALSE | E14: FALSE | F14: TRUE | G14: FALSE | H14: FALSE | I14: FALSE | J14: 20:00 hrs | K14: SI | L14: NO | M14: PENDING | O14: {=_xlfn.LET(_xlpm.activo,K14,_xlpm.horaTxt,J14,_xlpm.base,TODAY(),_xlpm.fechas,_xlpm.base+_xlfn.SEQUENCE(180,,0),_xlpm.hora,IF(ISNUMBER(_xlpm.horaTxt),_xlpm.horaTxt,IFERROR(TIMEVALUE(SUBSTITUTE(_xlpm.horaTxt," hrs","")),TIME(9,0,0))),_xlpm.dias,(C14*(WEEKDAY(_xlpm.fechas,2)=1))+(D14*(WEEKDAY(_xlpm.fechas,2)=2))+(E14*(WEEKDAY(_xlpm.fechas,2)=3))+(F14*(WEEKDAY(_xlpm.fechas,2)=4))+(G14*(WEEKDAY(_xlpm.fechas,2)=5))+(H14*(WEEKDAY(_xlpm.fechas,2)=6))+(I14*(WEEKDAY(_xlpm.fechas,2)=7)),_xlpm.validas,_xlfn._xlws.FILTER(_xlpm.fechas,(_xlpm.dias>0)*((_xlpm.fechas+_xlpm.hora)>=(NOW()-TIME(0,3,0)))),_xlpm.prox,_xlfn.TAKE(_xlpm.validas,4),IF(_xlpm.activo<>"SI","Inactivo",IF(SUMPRODUCT(--C14:I14)=0,"Manual / cuando aplique",_xlfn.TEXTJOIN(CHAR(10),TRUE,_xlfn.MAP(_xlpm.prox,_xlfn.LAMBDA(_xlpm.f,CHOOSE(WEEKDAY(_xlpm.f),"domingo","lunes","martes","miércoles","jueves","viernes","sábado")&" "&TEXT(_xlpm.f,"dd")&"/"&CHOOSE(MONTH(_xlpm.f),"Ene","Feb","Mar","Abr","May","Jun","Jul","Ago","Sep","Oct","Nov","Dic")&"/"&TEXT(_xlpm.f,"yyyy")&" "&TEXT(_xlpm.hora,"hh:mm")&" hrs"))))))} -> lunes 13/Jul/2026 20:00 hrs jueves 16/Jul/2026 20:00 hrs lunes 20/Jul/2026 20:00 hrs jueves 23/Jul/2026 20:00 hrs | P14: Como recordatorio, les pido que después de utilizar la secadora limpien el filtro. Es importante cuidarla para mantenerla en buen funcionamiento y evitar daños._x000D_ _x000D_ Gracias por su apoyo.
A15: ACME Residence 002 | B15: Estufa y luces | C15: FALSE | D15: TRUE | E15: FALSE | F15: TRUE | G15: FALSE | H15: FALSE | I15: FALSE | J15: 21:00 hrs | K15: SI | L15: NO | M15: PENDING | O15: {=_xlfn.LET(_xlpm.activo,K15,_xlpm.horaTxt,J15,_xlpm.base,TODAY(),_xlpm.fechas,_xlpm.base+_xlfn.SEQUENCE(180,,0),_xlpm.hora,IF(ISNUMBER(_xlpm.horaTxt),_xlpm.horaTxt,IFERROR(TIMEVALUE(SUBSTITUTE(_xlpm.horaTxt," hrs","")),TIME(9,0,0))),_xlpm.dias,(C15*(WEEKDAY(_xlpm.fechas,2)=1))+(D15*(WEEKDAY(_xlpm.fechas,2)=2))+(E15*(WEEKDAY(_xlpm.fechas,2)=3))+(F15*(WEEKDAY(_xlpm.fechas,2)=4))+(G15*(WEEKDAY(_xlpm.fechas,2)=5))+(H15*(WEEKDAY(_xlpm.fechas,2)=6))+(I15*(WEEKDAY(_xlpm.fechas,2)=7)),_xlpm.validas,_xlfn._xlws.FILTER(_xlpm.fechas,(_xlpm.dias>0)*((_xlpm.fechas+_xlpm.hora)>=(NOW()-TIME(0,3,0)))),_xlpm.prox,_xlfn.TAKE(_xlpm.validas,4),IF(_xlpm.activo<>"SI","Inactivo",IF(SUMPRODUCT(--C15:I15)=0,"Manual / cuando aplique",_xlfn.TEXTJOIN(CHAR(10),TRUE,_xlfn.MAP(_xlpm.prox,_xlfn.LAMBDA(_xlpm.f,CHOOSE(WEEKDAY(_xlpm.f),"domingo","lunes","martes","miércoles","jueves","viernes","sábado")&" "&TEXT(_xlpm.f,"dd")&"/"&CHOOSE(MONTH(_xlpm.f),"Ene","Feb","Mar","Abr","May","Jun","Jul","Ago","Sep","Oct","Nov","Dic")&"/"&TEXT(_xlpm.f,"yyyy")&" "&TEXT(_xlpm.hora,"hh:mm")&" hrs"))))))} -> martes 14/Jul/2026 21:00 hrs jueves 16/Jul/2026 21:00 hrs martes 21/Jul/2026 21:00 hrs jueves 23/Jul/2026 21:00 hrs | P15: Buenas noches a todos, chicos._x000D_ _x000D_ Como recordatorio, les pido que antes de dormir verifiquen que la estufa esté completamente apagada para evitar accidentes. Asimismo, favor de apagar todas las luces que no se estén utilizando._x000D_ _x000D_ Gracias por su apoyo y que tengan una excelente noche.
A16: ACME Residence 002 | B16: Ruido fin de semana | C16: FALSE | D16: FALSE | E16: FALSE | F16: FALSE | G16: FALSE | H16: TRUE | I16: FALSE | J16: 21:00 hrs | K16: SI | L16: NO | M16: PENDING | O16: {=_xlfn.LET(_xlpm.activo,K16,_xlpm.horaTxt,J16,_xlpm.base,TODAY(),_xlpm.fechas,_xlpm.base+_xlfn.SEQUENCE(180,,0),_xlpm.hora,IF(ISNUMBER(_xlpm.horaTxt),_xlpm.horaTxt,IFERROR(TIMEVALUE(SUBSTITUTE(_xlpm.horaTxt," hrs","")),TIME(9,0,0))),_xlpm.dias,(C16*(WEEKDAY(_xlpm.fechas,2)=1))+(D16*(WEEKDAY(_xlpm.fechas,2)=2))+(E16*(WEEKDAY(_xlpm.fechas,2)=3))+(F16*(WEEKDAY(_xlpm.fechas,2)=4))+(G16*(WEEKDAY(_xlpm.fechas,2)=5))+(H16*(WEEKDAY(_xlpm.fechas,2)=6))+(I16*(WEEKDAY(_xlpm.fechas,2)=7)),_xlpm.validas,_xlfn._xlws.FILTER(_xlpm.fechas,(_xlpm.dias>0)*((_xlpm.fechas+_xlpm.hora)>=(NOW()-TIME(0,3,0)))),_xlpm.prox,_xlfn.TAKE(_xlpm.validas,4),IF(_xlpm.activo<>"SI","Inactivo",IF(SUMPRODUCT(--C16:I16)=0,"Manual / cuando aplique",_xlfn.TEXTJOIN(CHAR(10),TRUE,_xlfn.MAP(_xlpm.prox,_xlfn.LAMBDA(_xlpm.f,CHOOSE(WEEKDAY(_xlpm.f),"domingo","lunes","martes","miércoles","jueves","viernes","sábado")&" "&TEXT(_xlpm.f,"dd")&"/"&CHOOSE(MONTH(_xlpm.f),"Ene","Feb","Mar","Abr","May","Jun","Jul","Ago","Sep","Oct","Nov","Dic")&"/"&TEXT(_xlpm.f,"yyyy")&" "&TEXT(_xlpm.hora,"hh:mm")&" hrs"))))))} -> sábado 11/Jul/2026 21:00 hrs sábado 18/Jul/2026 21:00 hrs sábado 25/Jul/2026 21:00 hrs sábado 01/Ago/2026 21:00 hrs | P16: Buenas noches a todos, chicos._x000D_ _x000D_ Solo como recordatorio, al ser fin de semana les pedimos de la manera más amable que moderen el ruido. Sabemos que muchos aprovechan estos días, pero también hay personas que necesitan descansar después de una semana de trabajo._x000D_ _x000D_ Seamos considerados con los demás y ayudemos a mantener un ambiente tranquilo para todos._x000D_ _x000D_ Muchas gracias por su apoyo. ¡Que tengan una excelente noche!
A17: CASA / GRUPO: ACME Residence 003
A18: ACME Residence 003 | B18: Limpieza y orden | C18: FALSE | D18: FALSE | E18: FALSE | F18: FALSE | G18: FALSE | H18: FALSE | I18: FALSE | K18: SI | L18: NO | M18: PENDING | O18: {=_xlfn.LET(_xlpm.activo,K18,_xlpm.horaTxt,J18,_xlpm.base,TODAY(),_xlpm.fechas,_xlpm.base+_xlfn.SEQUENCE(180,,0),_xlpm.hora,IF(ISNUMBER(_xlpm.horaTxt),_xlpm.horaTxt,IFERROR(TIMEVALUE(SUBSTITUTE(_xlpm.horaTxt," hrs","")),TIME(9,0,0))),_xlpm.dias,(C18*(WEEKDAY(_xlpm.fechas,2)=1))+(D18*(WEEKDAY(_xlpm.fechas,2)=2))+(E18*(WEEKDAY(_xlpm.fechas,2)=3))+(F18*(WEEKDAY(_xlpm.fechas,2)=4))+(G18*(WEEKDAY(_xlpm.fechas,2)=5))+(H18*(WEEKDAY(_xlpm.fechas,2)=6))+(I18*(WEEKDAY(_xlpm.fechas,2)=7)),_xlpm.validas,_xlfn._xlws.FILTER(_xlpm.fechas,(_xlpm.dias>0)*((_xlpm.fechas+_xlpm.hora)>=(NOW()-TIME(0,3,0)))),_xlpm.prox,_xlfn.TAKE(_xlpm.validas,4),IF(_xlpm.activo<>"SI","Inactivo",IF(SUMPRODUCT(--C18:I18)=0,"Manual / cuando aplique",_xlfn.TEXTJOIN(CHAR(10),TRUE,_xlfn.MAP(_xlpm.prox,_xlfn.LAMBDA(_xlpm.f,CHOOSE(WEEKDAY(_xlpm.f),"domingo","lunes","martes","miércoles","jueves","viernes","sábado")&" "&TEXT(_xlpm.f,"dd")&"/"&CHOOSE(MONTH(_xlpm.f),"Ene","Feb","Mar","Abr","May","Jun","Jul","Ago","Sep","Oct","Nov","Dic")&"/"&TEXT(_xlpm.f,"yyyy")&" "&TEXT(_xlpm.hora,"hh:mm")&" hrs"))))))} -> Manual / cuando aplique | P18: Buenos días chicos,_x000D_ _x000D_ Como recordatorio, les pido de su amable apoyo para:_x000D_ _x000D_ * Lavar, secar y guardar los trastes que utilicen._x000D_ * Barrer la cocina y dejarla limpia para que la siguiente persona la encuentre en las mismas condiciones._x000D_ * Apagar todas las luces que no estén utilizando._x000D_ * Colocar las sillas del comedor en su lugar después de usarlas._x000D_ _x000D_ Muchas gracias por su colaboración para mantener la casa limpia y ordenada.
A19: ACME Residence 003 | B19: Lavandería - horario | C19: TRUE | D19: FALSE | E19: FALSE | F19: TRUE | G19: FALSE | H19: FALSE | I19: FALSE | J19: 19:00 hrs | K19: SI | L19: NO | M19: PENDING | O19: {=_xlfn.LET(_xlpm.activo,K19,_xlpm.horaTxt,J19,_xlpm.base,TODAY(),_xlpm.fechas,_xlpm.base+_xlfn.SEQUENCE(180,,0),_xlpm.hora,IF(ISNUMBER(_xlpm.horaTxt),_xlpm.horaTxt,IFERROR(TIMEVALUE(SUBSTITUTE(_xlpm.horaTxt," hrs","")),TIME(9,0,0))),_xlpm.dias,(C19*(WEEKDAY(_xlpm.fechas,2)=1))+(D19*(WEEKDAY(_xlpm.fechas,2)=2))+(E19*(WEEKDAY(_xlpm.fechas,2)=3))+(F19*(WEEKDAY(_xlpm.fechas,2)=4))+(G19*(WEEKDAY(_xlpm.fechas,2)=5))+(H19*(WEEKDAY(_xlpm.fechas,2)=6))+(I19*(WEEKDAY(_xlpm.fechas,2)=7)),_xlpm.validas,_xlfn._xlws.FILTER(_xlpm.fechas,(_xlpm.dias>0)*((_xlpm.fechas+_xlpm.hora)>=(NOW()-TIME(0,3,0)))),_xlpm.prox,_xlfn.TAKE(_xlpm.validas,4),IF(_xlpm.activo<>"SI","Inactivo",IF(SUMPRODUCT(--C19:I19)=0,"Manual / cuando aplique",_xlfn.TEXTJOIN(CHAR(10),TRUE,_xlfn.MAP(_xlpm.prox,_xlfn.LAMBDA(_xlpm.f,CHOOSE(WEEKDAY(_xlpm.f),"domingo","lunes","martes","miércoles","jueves","viernes","sábado")&" "&TEXT(_xlpm.f,"dd")&"/"&CHOOSE(MONTH(_xlpm.f),"Ene","Feb","Mar","Abr","May","Jun","Jul","Ago","Sep","Oct","Nov","Dic")&"/"&TEXT(_xlpm.f,"yyyy")&" "&TEXT(_xlpm.hora,"hh:mm")&" hrs"))))))} -> lunes 13/Jul/2026 19:00 hrs jueves 16/Jul/2026 19:00 hrs lunes 20/Jul/2026 19:00 hrs jueves 23/Jul/2026 19:00 hrs | P19: Buenas tardes, chicos._x000D_ _x000D_ Solo para confirmarles que el horario de lavado ya está disponible. Pueden utilizar la lavandería de 7:00 p. m. a 10:30 p. m._x000D_ _x000D_ Gracias.
A20: ACME Residence 003 | B20: Lavandería - filtro secadora | C20: TRUE | D20: FALSE | E20: FALSE | F20: TRUE | G20: FALSE | H20: FALSE | I20: FALSE | J20: 20:00 hrs | K20: SI | L20: NO | M20: PENDING | O20: {=_xlfn.LET(_xlpm.activo,K20,_xlpm.horaTxt,J20,_xlpm.base,TODAY(),_xlpm.fechas,_xlpm.base+_xlfn.SEQUENCE(180,,0),_xlpm.hora,IF(ISNUMBER(_xlpm.horaTxt),_xlpm.horaTxt,IFERROR(TIMEVALUE(SUBSTITUTE(_xlpm.horaTxt," hrs","")),TIME(9,0,0))),_xlpm.dias,(C20*(WEEKDAY(_xlpm.fechas,2)=1))+(D20*(WEEKDAY(_xlpm.fechas,2)=2))+(E20*(WEEKDAY(_xlpm.fechas,2)=3))+(F20*(WEEKDAY(_xlpm.fechas,2)=4))+(G20*(WEEKDAY(_xlpm.fechas,2)=5))+(H20*(WEEKDAY(_xlpm.fechas,2)=6))+(I20*(WEEKDAY(_xlpm.fechas,2)=7)),_xlpm.validas,_xlfn._xlws.FILTER(_xlpm.fechas,(_xlpm.dias>0)*((_xlpm.fechas+_xlpm.hora)>=(NOW()-TIME(0,3,0)))),_xlpm.prox,_xlfn.TAKE(_xlpm.validas,4),IF(_xlpm.activo<>"SI","Inactivo",IF(SUMPRODUCT(--C20:I20)=0,"Manual / cuando aplique",_xlfn.TEXTJOIN(CHAR(10),TRUE,_xlfn.MAP(_xlpm.prox,_xlfn.LAMBDA(_xlpm.f,CHOOSE(WEEKDAY(_xlpm.f),"domingo","lunes","martes","miércoles","jueves","viernes","sábado")&" "&TEXT(_xlpm.f,"dd")&"/"&CHOOSE(MONTH(_xlpm.f),"Ene","Feb","Mar","Abr","May","Jun","Jul","Ago","Sep","Oct","Nov","Dic")&"/"&TEXT(_xlpm.f,"yyyy")&" "&TEXT(_xlpm.hora,"hh:mm")&" hrs"))))))} -> lunes 13/Jul/2026 20:00 hrs jueves 16/Jul/2026 20:00 hrs lunes 20/Jul/2026 20:00 hrs jueves 23/Jul/2026 20:00 hrs | P20: Como recordatorio, les pido que después de utilizar la secadora limpien el filtro. Es importante cuidarla para mantenerla en buen funcionamiento y evitar daños._x000D_ _x000D_ Gracias por su apoyo.
A21: ACME Residence 003 | B21: Estufa y luces | C21: FALSE | D21: TRUE | E21: FALSE | F21: TRUE | G21: FALSE | H21: FALSE | I21: FALSE | J21: 21:00 hrs | K21: SI | L21: NO | M21: PENDING | O21: {=_xlfn.LET(_xlpm.activo,K21,_xlpm.horaTxt,J21,_xlpm.base,TODAY(),_xlpm.fechas,_xlpm.base+_xlfn.SEQUENCE(180,,0),_xlpm.hora,IF(ISNUMBER(_xlpm.horaTxt),_xlpm.horaTxt,IFERROR(TIMEVALUE(SUBSTITUTE(_xlpm.horaTxt," hrs","")),TIME(9,0,0))),_xlpm.dias,(C21*(WEEKDAY(_xlpm.fechas,2)=1))+(D21*(WEEKDAY(_xlpm.fechas,2)=2))+(E21*(WEEKDAY(_xlpm.fechas,2)=3))+(F21*(WEEKDAY(_xlpm.fechas,2)=4))+(G21*(WEEKDAY(_xlpm.fechas,2)=5))+(H21*(WEEKDAY(_xlpm.fechas,2)=6))+(I21*(WEEKDAY(_xlpm.fechas,2)=7)),_xlpm.validas,_xlfn._xlws.FILTER(_xlpm.fechas,(_xlpm.dias>0)*((_xlpm.fechas+_xlpm.hora)>=(NOW()-TIME(0,3,0)))),_xlpm.prox,_xlfn.TAKE(_xlpm.validas,4),IF(_xlpm.activo<>"SI","Inactivo",IF(SUMPRODUCT(--C21:I21)=0,"Manual / cuando aplique",_xlfn.TEXTJOIN(CHAR(10),TRUE,_xlfn.MAP(_xlpm.prox,_xlfn.LAMBDA(_xlpm.f,CHOOSE(WEEKDAY(_xlpm.f),"domingo","lunes","martes","miércoles","jueves","viernes","sábado")&" "&TEXT(_xlpm.f,"dd")&"/"&CHOOSE(MONTH(_xlpm.f),"Ene","Feb","Mar","Abr","May","Jun","Jul","Ago","Sep","Oct","Nov","Dic")&"/"&TEXT(_xlpm.f,"yyyy")&" "&TEXT(_xlpm.hora,"hh:mm")&" hrs"))))))} -> martes 14/Jul/2026 21:00 hrs jueves 16/Jul/2026 21:00 hrs martes 21/Jul/2026 21:00 hrs jueves 23/Jul/2026 21:00 hrs | P21: Buenas noches a todos, chicos._x000D_ _x000D_ Como recordatorio, les pido que antes de dormir verifiquen que la estufa esté completamente apagada para evitar accidentes. Asimismo, favor de apagar todas las luces que no se estén utilizando._x000D_ _x000D_ Gracias por su apoyo y que tengan una excelente noche.
A22: ACME Residence 003 | B22: Ruido fin de semana | C22: FALSE | D22: FALSE | E22: FALSE | F22: FALSE | G22: FALSE | H22: TRUE | I22: FALSE | J22: 21:00 hrs | K22: SI | L22: NO | M22: PENDING | O22: {=_xlfn.LET(_xlpm.activo,K22,_xlpm.horaTxt,J22,_xlpm.base,TODAY(),_xlpm.fechas,_xlpm.base+_xlfn.SEQUENCE(180,,0),_xlpm.hora,IF(ISNUMBER(_xlpm.horaTxt),_xlpm.horaTxt,IFERROR(TIMEVALUE(SUBSTITUTE(_xlpm.horaTxt," hrs","")),TIME(9,0,0))),_xlpm.dias,(C22*(WEEKDAY(_xlpm.fechas,2)=1))+(D22*(WEEKDAY(_xlpm.fechas,2)=2))+(E22*(WEEKDAY(_xlpm.fechas,2)=3))+(F22*(WEEKDAY(_xlpm.fechas,2)=4))+(G22*(WEEKDAY(_xlpm.fechas,2)=5))+(H22*(WEEKDAY(_xlpm.fechas,2)=6))+(I22*(WEEKDAY(_xlpm.fechas,2)=7)),_xlpm.validas,_xlfn._xlws.FILTER(_xlpm.fechas,(_xlpm.dias>0)*((_xlpm.fechas+_xlpm.hora)>=(NOW()-TIME(0,3,0)))),_xlpm.prox,_xlfn.TAKE(_xlpm.validas,4),IF(_xlpm.activo<>"SI","Inactivo",IF(SUMPRODUCT(--C22:I22)=0,"Manual / cuando aplique",_xlfn.TEXTJOIN(CHAR(10),TRUE,_xlfn.MAP(_xlpm.prox,_xlfn.LAMBDA(_xlpm.f,CHOOSE(WEEKDAY(_xlpm.f),"domingo","lunes","martes","miércoles","jueves","viernes","sábado")&" "&TEXT(_xlpm.f,"dd")&"/"&CHOOSE(MONTH(_xlpm.f),"Ene","Feb","Mar","Abr","May","Jun","Jul","Ago","Sep","Oct","Nov","Dic")&"/"&TEXT(_xlpm.f,"yyyy")&" "&TEXT(_xlpm.hora,"hh:mm")&" hrs"))))))} -> sábado 11/Jul/2026 21:00 hrs sábado 18/Jul/2026 21:00 hrs sábado 25/Jul/2026 21:00 hrs sábado 01/Ago/2026 21:00 hrs | P22: Buenas noches a todos, chicos._x000D_ _x000D_ Solo como recordatorio, al ser fin de semana les pedimos de la manera más amable que moderen el ruido. Sabemos que muchos aprovechan estos días, pero también hay personas que necesitan descansar después de una semana de trabajo._x000D_ _x000D_ Seamos considerados con los demás y ayudemos a mantener un ambiente tranquilo para todos._x000D_ _x000D_ Muchas gracias por su apoyo. ¡Que tengan una excelente noche!
A23: CASA / GRUPO: ACME Residence 004
A24: ACME Residence 004 | B24: Limpieza y orden | C24: FALSE | D24: FALSE | E24: FALSE | F24: FALSE | G24: FALSE | H24: FALSE | I24: FALSE | K24: SI | L24: NO | M24: PENDING | O24: {=_xlfn.LET(_xlpm.activo,K24,_xlpm.horaTxt,J24,_xlpm.base,TODAY(),_xlpm.fechas,_xlpm.base+_xlfn.SEQUENCE(180,,0),_xlpm.hora,IF(ISNUMBER(_xlpm.horaTxt),_xlpm.horaTxt,IFERROR(TIMEVALUE(SUBSTITUTE(_xlpm.horaTxt," hrs","")),TIME(9,0,0))),_xlpm.dias,(C24*(WEEKDAY(_xlpm.fechas,2)=1))+(D24*(WEEKDAY(_xlpm.fechas,2)=2))+(E24*(WEEKDAY(_xlpm.fechas,2)=3))+(F24*(WEEKDAY(_xlpm.fechas,2)=4))+(G24*(WEEKDAY(_xlpm.fechas,2)=5))+(H24*(WEEKDAY(_xlpm.fechas,2)=6))+(I24*(WEEKDAY(_xlpm.fechas,2)=7)),_xlpm.validas,_xlfn._xlws.FILTER(_xlpm.fechas,(_xlpm.dias>0)*((_xlpm.fechas+_xlpm.hora)>=(NOW()-TIME(0,3,0)))),_xlpm.prox,_xlfn.TAKE(_xlpm.validas,4),IF(_xlpm.activo<>"SI","Inactivo",IF(SUMPRODUCT(--C24:I24)=0,"Manual / cuando aplique",_xlfn.TEXTJOIN(CHAR(10),TRUE,_xlfn.MAP(_xlpm.prox,_xlfn.LAMBDA(_xlpm.f,CHOOSE(WEEKDAY(_xlpm.f),"domingo","lunes","martes","miércoles","jueves","viernes","sábado")&" "&TEXT(_xlpm.f,"dd")&"/"&CHOOSE(MONTH(_xlpm.f),"Ene","Feb","Mar","Abr","May","Jun","Jul","Ago","Sep","Oct","Nov","Dic")&"/"&TEXT(_xlpm.f,"yyyy")&" "&TEXT(_xlpm.hora,"hh:mm")&" hrs"))))))} -> Manual / cuando aplique | P24: Buenos días chicos,_x000D_ _x000D_ Como recordatorio, les pido de su amable apoyo para:_x000D_ _x000D_ * Lavar, secar y guardar los trastes que utilicen._x000D_ * Barrer la cocina y dejarla limpia para que la siguiente persona la encuentre en las mismas condiciones._x000D_ * Apagar todas las luces que no estén utilizando._x000D_ * Colocar las sillas del comedor en su lugar después de usarlas._x000D_ _x000D_ Muchas gracias por su colaboración para mantener la casa limpia y ordenada.
A25: ACME Residence 004 | B25: Lavandería - horario | C25: TRUE | D25: FALSE | E25: FALSE | F25: TRUE | G25: FALSE | H25: FALSE | I25: FALSE | J25: 19:00 hrs | K25: SI | L25: NO | M25: PENDING | O25: {=_xlfn.LET(_xlpm.activo,K25,_xlpm.horaTxt,J25,_xlpm.base,TODAY(),_xlpm.fechas,_xlpm.base+_xlfn.SEQUENCE(180,,0),_xlpm.hora,IF(ISNUMBER(_xlpm.horaTxt),_xlpm.horaTxt,IFERROR(TIMEVALUE(SUBSTITUTE(_xlpm.horaTxt," hrs","")),TIME(9,0,0))),_xlpm.dias,(C25*(WEEKDAY(_xlpm.fechas,2)=1))+(D25*(WEEKDAY(_xlpm.fechas,2)=2))+(E25*(WEEKDAY(_xlpm.fechas,2)=3))+(F25*(WEEKDAY(_xlpm.fechas,2)=4))+(G25*(WEEKDAY(_xlpm.fechas,2)=5))+(H25*(WEEKDAY(_xlpm.fechas,2)=6))+(I25*(WEEKDAY(_xlpm.fechas,2)=7)),_xlpm.validas,_xlfn._xlws.FILTER(_xlpm.fechas,(_xlpm.dias>0)*((_xlpm.fechas+_xlpm.hora)>=(NOW()-TIME(0,3,0)))),_xlpm.prox,_xlfn.TAKE(_xlpm.validas,4),IF(_xlpm.activo<>"SI","Inactivo",IF(SUMPRODUCT(--C25:I25)=0,"Manual / cuando aplique",_xlfn.TEXTJOIN(CHAR(10),TRUE,_xlfn.MAP(_xlpm.prox,_xlfn.LAMBDA(_xlpm.f,CHOOSE(WEEKDAY(_xlpm.f),"domingo","lunes","martes","miércoles","jueves","viernes","sábado")&" "&TEXT(_xlpm.f,"dd")&"/"&CHOOSE(MONTH(_xlpm.f),"Ene","Feb","Mar","Abr","May","Jun","Jul","Ago","Sep","Oct","Nov","Dic")&"/"&TEXT(_xlpm.f,"yyyy")&" "&TEXT(_xlpm.hora,"hh:mm")&" hrs"))))))} -> lunes 13/Jul/2026 19:00 hrs jueves 16/Jul/2026 19:00 hrs lunes 20/Jul/2026 19:00 hrs jueves 23/Jul/2026 19:00 hrs | P25: Buenas tardes, chicos._x000D_ _x000D_ Solo para confirmarles que el horario de lavado ya está disponible. Pueden utilizar la lavandería de 7:00 p. m. a 10:30 p. m._x000D_ _x000D_ Gracias.
A26: ACME Residence 004 | B26: Lavandería - filtro secadora | C26: TRUE | D26: FALSE | E26: FALSE | F26: TRUE | G26: FALSE | H26: FALSE | I26: FALSE | J26: 20:00 hrs | K26: SI | L26: NO | M26: PENDING | O26: {=_xlfn.LET(_xlpm.activo,K26,_xlpm.horaTxt,J26,_xlpm.base,TODAY(),_xlpm.fechas,_xlpm.base+_xlfn.SEQUENCE(180,,0),_xlpm.hora,IF(ISNUMBER(_xlpm.horaTxt),_xlpm.horaTxt,IFERROR(TIMEVALUE(SUBSTITUTE(_xlpm.horaTxt," hrs","")),TIME(9,0,0))),_xlpm.dias,(C26*(WEEKDAY(_xlpm.fechas,2)=1))+(D26*(WEEKDAY(_xlpm.fechas,2)=2))+(E26*(WEEKDAY(_xlpm.fechas,2)=3))+(F26*(WEEKDAY(_xlpm.fechas,2)=4))+(G26*(WEEKDAY(_xlpm.fechas,2)=5))+(H26*(WEEKDAY(_xlpm.fechas,2)=6))+(I26*(WEEKDAY(_xlpm.fechas,2)=7)),_xlpm.validas,_xlfn._xlws.FILTER(_xlpm.fechas,(_xlpm.dias>0)*((_xlpm.fechas+_xlpm.hora)>=(NOW()-TIME(0,3,0)))),_xlpm.prox,_xlfn.TAKE(_xlpm.validas,4),IF(_xlpm.activo<>"SI","Inactivo",IF(SUMPRODUCT(--C26:I26)=0,"Manual / cuando aplique",_xlfn.TEXTJOIN(CHAR(10),TRUE,_xlfn.MAP(_xlpm.prox,_xlfn.LAMBDA(_xlpm.f,CHOOSE(WEEKDAY(_xlpm.f),"domingo","lunes","martes","miércoles","jueves","viernes","sábado")&" "&TEXT(_xlpm.f,"dd")&"/"&CHOOSE(MONTH(_xlpm.f),"Ene","Feb","Mar","Abr","May","Jun","Jul","Ago","Sep","Oct","Nov","Dic")&"/"&TEXT(_xlpm.f,"yyyy")&" "&TEXT(_xlpm.hora,"hh:mm")&" hrs"))))))} -> lunes 13/Jul/2026 20:00 hrs jueves 16/Jul/2026 20:00 hrs lunes 20/Jul/2026 20:00 hrs jueves 23/Jul/2026 20:00 hrs | P26: Como recordatorio, les pido que después de utilizar la secadora limpien el filtro. Es importante cuidarla para mantenerla en buen funcionamiento y evitar daños._x000D_ _x000D_ Gracias por su apoyo.
A27: ACME Residence 004 | B27: Estufa y luces | C27: FALSE | D27: TRUE | E27: FALSE | F27: TRUE | G27: FALSE | H27: FALSE | I27: FALSE | J27: 21:00 hrs | K27: SI | L27: NO | M27: PENDING | O27: {=_xlfn.LET(_xlpm.activo,K27,_xlpm.horaTxt,J27,_xlpm.base,TODAY(),_xlpm.fechas,_xlpm.base+_xlfn.SEQUENCE(180,,0),_xlpm.hora,IF(ISNUMBER(_xlpm.horaTxt),_xlpm.horaTxt,IFERROR(TIMEVALUE(SUBSTITUTE(_xlpm.horaTxt," hrs","")),TIME(9,0,0))),_xlpm.dias,(C27*(WEEKDAY(_xlpm.fechas,2)=1))+(D27*(WEEKDAY(_xlpm.fechas,2)=2))+(E27*(WEEKDAY(_xlpm.fechas,2)=3))+(F27*(WEEKDAY(_xlpm.fechas,2)=4))+(G27*(WEEKDAY(_xlpm.fechas,2)=5))+(H27*(WEEKDAY(_xlpm.fechas,2)=6))+(I27*(WEEKDAY(_xlpm.fechas,2)=7)),_xlpm.validas,_xlfn._xlws.FILTER(_xlpm.fechas,(_xlpm.dias>0)*((_xlpm.fechas+_xlpm.hora)>=(NOW()-TIME(0,3,0)))),_xlpm.prox,_xlfn.TAKE(_xlpm.validas,4),IF(_xlpm.activo<>"SI","Inactivo",IF(SUMPRODUCT(--C27:I27)=0,"Manual / cuando aplique",_xlfn.TEXTJOIN(CHAR(10),TRUE,_xlfn.MAP(_xlpm.prox,_xlfn.LAMBDA(_xlpm.f,CHOOSE(WEEKDAY(_xlpm.f),"domingo","lunes","martes","miércoles","jueves","viernes","sábado")&" "&TEXT(_xlpm.f,"dd")&"/"&CHOOSE(MONTH(_xlpm.f),"Ene","Feb","Mar","Abr","May","Jun","Jul","Ago","Sep","Oct","Nov","Dic")&"/"&TEXT(_xlpm.f,"yyyy")&" "&TEXT(_xlpm.hora,"hh:mm")&" hrs"))))))} -> martes 14/Jul/2026 21:00 hrs jueves 16/Jul/2026 21:00 hrs martes 21/Jul/2026 21:00 hrs jueves 23/Jul/2026 21:00 hrs | P27: Buenas noches a todos, chicos._x000D_ _x000D_ Como recordatorio, les pido que antes de dormir verifiquen que la estufa esté completamente apagada para evitar accidentes. Asimismo, favor de apagar todas las luces que no se estén utilizando._x000D_ _x000D_ Gracias por su apoyo y que tengan una excelente noche.
A28: ACME Residence 004 | B28: Ruido fin de semana | C28: FALSE | D28: FALSE | E28: FALSE | F28: FALSE | G28: FALSE | H28: TRUE | I28: FALSE | J28: 21:00 hrs | K28: SI | L28: NO | M28: PENDING | O28: {=_xlfn.LET(_xlpm.activo,K28,_xlpm.horaTxt,J28,_xlpm.base,TODAY(),_xlpm.fechas,_xlpm.base+_xlfn.SEQUENCE(180,,0),_xlpm.hora,IF(ISNUMBER(_xlpm.horaTxt),_xlpm.horaTxt,IFERROR(TIMEVALUE(SUBSTITUTE(_xlpm.horaTxt," hrs","")),TIME(9,0,0))),_xlpm.dias,(C28*(WEEKDAY(_xlpm.fechas,2)=1))+(D28*(WEEKDAY(_xlpm.fechas,2)=2))+(E28*(WEEKDAY(_xlpm.fechas,2)=3))+(F28*(WEEKDAY(_xlpm.fechas,2)=4))+(G28*(WEEKDAY(_xlpm.fechas,2)=5))+(H28*(WEEKDAY(_xlpm.fechas,2)=6))+(I28*(WEEKDAY(_xlpm.fechas,2)=7)),_xlpm.validas,_xlfn._xlws.FILTER(_xlpm.fechas,(_xlpm.dias>0)*((_xlpm.fechas+_xlpm.hora)>=(NOW()-TIME(0,3,0)))),_xlpm.prox,_xlfn.TAKE(_xlpm.validas,4),IF(_xlpm.activo<>"SI","Inactivo",IF(SUMPRODUCT(--C28:I28)=0,"Manual / cuando aplique",_xlfn.TEXTJOIN(CHAR(10),TRUE,_xlfn.MAP(_xlpm.prox,_xlfn.LAMBDA(_xlpm.f,CHOOSE(WEEKDAY(_xlpm.f),"domingo","lunes","martes","miércoles","jueves","viernes","sábado")&" "&TEXT(_xlpm.f,"dd")&"/"&CHOOSE(MONTH(_xlpm.f),"Ene","Feb","Mar","Abr","May","Jun","Jul","Ago","Sep","Oct","Nov","Dic")&"/"&TEXT(_xlpm.f,"yyyy")&" "&TEXT(_xlpm.hora,"hh:mm")&" hrs"))))))} -> sábado 11/Jul/2026 21:00 hrs sábado 18/Jul/2026 21:00 hrs sábado 25/Jul/2026 21:00 hrs sábado 01/Ago/2026 21:00 hrs | P28: Buenas noches a todos, chicos._x000D_ _x000D_ Solo como recordatorio, al ser fin de semana les pedimos de la manera más amable que moderen el ruido. Sabemos que muchos aprovechan estos días, pero también hay personas que necesitan descansar después de una semana de trabajo._x000D_ _x000D_ Seamos considerados con los demás y ayudemos a mantener un ambiente tranquilo para todos._x000D_ _x000D_ Muchas gracias por su apoyo. ¡Que tengan una excelente noche!
A29: CASA / GRUPO: ACME Residence 005
A30: ACME Residence 005 | B30: Limpieza y orden | C30: FALSE | D30: FALSE | E30: FALSE | F30: FALSE | G30: FALSE | H30: FALSE | I30: FALSE | K30: SI | L30: NO | M30: PENDING | O30: {=_xlfn.LET(_xlpm.activo,K30,_xlpm.horaTxt,J30,_xlpm.base,TODAY(),_xlpm.fechas,_xlpm.base+_xlfn.SEQUENCE(180,,0),_xlpm.hora,IF(ISNUMBER(_xlpm.horaTxt),_xlpm.horaTxt,IFERROR(TIMEVALUE(SUBSTITUTE(_xlpm.horaTxt," hrs","")),TIME(9,0,0))),_xlpm.dias,(C30*(WEEKDAY(_xlpm.fechas,2)=1))+(D30*(WEEKDAY(_xlpm.fechas,2)=2))+(E30*(WEEKDAY(_xlpm.fechas,2)=3))+(F30*(WEEKDAY(_xlpm.fechas,2)=4))+(G30*(WEEKDAY(_xlpm.fechas,2)=5))+(H30*(WEEKDAY(_xlpm.fechas,2)=6))+(I30*(WEEKDAY(_xlpm.fechas,2)=7)),_xlpm.validas,_xlfn._xlws.FILTER(_xlpm.fechas,(_xlpm.dias>0)*((_xlpm.fechas+_xlpm.hora)>=(NOW()-TIME(0,3,0)))),_xlpm.prox,_xlfn.TAKE(_xlpm.validas,4),IF(_xlpm.activo<>"SI","Inactivo",IF(SUMPRODUCT(--C30:I30)=0,"Manual / cuando aplique",_xlfn.TEXTJOIN(CHAR(10),TRUE,_xlfn.MAP(_xlpm.prox,_xlfn.LAMBDA(_xlpm.f,CHOOSE(WEEKDAY(_xlpm.f),"domingo","lunes","martes","miércoles","jueves","viernes","sábado")&" "&TEXT(_xlpm.f,"dd")&"/"&CHOOSE(MONTH(_xlpm.f),"Ene","Feb","Mar","Abr","May","Jun","Jul","Ago","Sep","Oct","Nov","Dic")&"/"&TEXT(_xlpm.f,"yyyy")&" "&TEXT(_xlpm.hora,"hh:mm")&" hrs"))))))} -> Manual / cuando aplique | P30: Buenos días chicos,_x000D_ _x000D_ Como recordatorio, les pido de su amable apoyo para:_x000D_ _x000D_ * Lavar, secar y guardar los trastes que utilicen._x000D_ * Barrer la cocina y dejarla limpia para que la siguiente persona la encuentre en las mismas condiciones._x000D_ * Apagar todas las luces que no estén utilizando._x000D_ * Colocar las sillas del comedor en su lugar después de usarlas._x000D_ _x000D_ Muchas gracias por su colaboración para mantener la casa limpia y ordenada.
A31: ACME Residence 005 | B31: Lavandería - horario | C31: TRUE | D31: FALSE | E31: FALSE | F31: TRUE | G31: FALSE | H31: FALSE | I31: FALSE | J31: 19:00 hrs | K31: SI | L31: NO | M31: PENDING | O31: {=_xlfn.LET(_xlpm.activo,K31,_xlpm.horaTxt,J31,_xlpm.base,TODAY(),_xlpm.fechas,_xlpm.base+_xlfn.SEQUENCE(180,,0),_xlpm.hora,IF(ISNUMBER(_xlpm.horaTxt),_xlpm.horaTxt,IFERROR(TIMEVALUE(SUBSTITUTE(_xlpm.horaTxt," hrs","")),TIME(9,0,0))),_xlpm.dias,(C31*(WEEKDAY(_xlpm.fechas,2)=1))+(D31*(WEEKDAY(_xlpm.fechas,2)=2))+(E31*(WEEKDAY(_xlpm.fechas,2)=3))+(F31*(WEEKDAY(_xlpm.fechas,2)=4))+(G31*(WEEKDAY(_xlpm.fechas,2)=5))+(H31*(WEEKDAY(_xlpm.fechas,2)=6))+(I31*(WEEKDAY(_xlpm.fechas,2)=7)),_xlpm.validas,_xlfn._xlws.FILTER(_xlpm.fechas,(_xlpm.dias>0)*((_xlpm.fechas+_xlpm.hora)>=(NOW()-TIME(0,3,0)))),_xlpm.prox,_xlfn.TAKE(_xlpm.validas,4),IF(_xlpm.activo<>"SI","Inactivo",IF(SUMPRODUCT(--C31:I31)=0,"Manual / cuando aplique",_xlfn.TEXTJOIN(CHAR(10),TRUE,_xlfn.MAP(_xlpm.prox,_xlfn.LAMBDA(_xlpm.f,CHOOSE(WEEKDAY(_xlpm.f),"domingo","lunes","martes","miércoles","jueves","viernes","sábado")&" "&TEXT(_xlpm.f,"dd")&"/"&CHOOSE(MONTH(_xlpm.f),"Ene","Feb","Mar","Abr","May","Jun","Jul","Ago","Sep","Oct","Nov","Dic")&"/"&TEXT(_xlpm.f,"yyyy")&" "&TEXT(_xlpm.hora,"hh:mm")&" hrs"))))))} -> lunes 13/Jul/2026 19:00 hrs jueves 16/Jul/2026 19:00 hrs lunes 20/Jul/2026 19:00 hrs jueves 23/Jul/2026 19:00 hrs | P31: Buenas tardes, chicos._x000D_ _x000D_ Solo para confirmarles que el horario de lavado ya está disponible. Pueden utilizar la lavandería de 7:00 p. m. a 10:30 p. m._x000D_ _x000D_ Gracias.
A32: ACME Residence 005 | B32: Lavandería - filtro secadora | C32: TRUE | D32: FALSE | E32: FALSE | F32: TRUE | G32: FALSE | H32: FALSE | I32: FALSE | J32: 20:00 hrs | K32: SI | L32: NO | M32: PENDING | O32: {=_xlfn.LET(_xlpm.activo,K32,_xlpm.horaTxt,J32,_xlpm.base,TODAY(),_xlpm.fechas,_xlpm.base+_xlfn.SEQUENCE(180,,0),_xlpm.hora,IF(ISNUMBER(_xlpm.horaTxt),_xlpm.horaTxt,IFERROR(TIMEVALUE(SUBSTITUTE(_xlpm.horaTxt," hrs","")),TIME(9,0,0))),_xlpm.dias,(C32*(WEEKDAY(_xlpm.fechas,2)=1))+(D32*(WEEKDAY(_xlpm.fechas,2)=2))+(E32*(WEEKDAY(_xlpm.fechas,2)=3))+(F32*(WEEKDAY(_xlpm.fechas,2)=4))+(G32*(WEEKDAY(_xlpm.fechas,2)=5))+(H32*(WEEKDAY(_xlpm.fechas,2)=6))+(I32*(WEEKDAY(_xlpm.fechas,2)=7)),_xlpm.validas,_xlfn._xlws.FILTER(_xlpm.fechas,(_xlpm.dias>0)*((_xlpm.fechas+_xlpm.hora)>=(NOW()-TIME(0,3,0)))),_xlpm.prox,_xlfn.TAKE(_xlpm.validas,4),IF(_xlpm.activo<>"SI","Inactivo",IF(SUMPRODUCT(--C32:I32)=0,"Manual / cuando aplique",_xlfn.TEXTJOIN(CHAR(10),TRUE,_xlfn.MAP(_xlpm.prox,_xlfn.LAMBDA(_xlpm.f,CHOOSE(WEEKDAY(_xlpm.f),"domingo","lunes","martes","miércoles","jueves","viernes","sábado")&" "&TEXT(_xlpm.f,"dd")&"/"&CHOOSE(MONTH(_xlpm.f),"Ene","Feb","Mar","Abr","May","Jun","Jul","Ago","Sep","Oct","Nov","Dic")&"/"&TEXT(_xlpm.f,"yyyy")&" "&TEXT(_xlpm.hora,"hh:mm")&" hrs"))))))} -> lunes 13/Jul/2026 20:00 hrs jueves 16/Jul/2026 20:00 hrs lunes 20/Jul/2026 20:00 hrs jueves 23/Jul/2026 20:00 hrs | P32: Como recordatorio, les pido que después de utilizar la secadora limpien el filtro. Es importante cuidarla para mantenerla en buen funcionamiento y evitar daños._x000D_ _x000D_ Gracias por su apoyo.
A33: ACME Residence 005 | B33: Estufa y luces | C33: FALSE | D33: TRUE | E33: FALSE | F33: TRUE | G33: FALSE | H33: FALSE | I33: FALSE | J33: 21:00 hrs | K33: SI | L33: NO | M33: PENDING | O33: {=_xlfn.LET(_xlpm.activo,K33,_xlpm.horaTxt,J33,_xlpm.base,TODAY(),_xlpm.fechas,_xlpm.base+_xlfn.SEQUENCE(180,,0),_xlpm.hora,IF(ISNUMBER(_xlpm.horaTxt),_xlpm.horaTxt,IFERROR(TIMEVALUE(SUBSTITUTE(_xlpm.horaTxt," hrs","")),TIME(9,0,0))),_xlpm.dias,(C33*(WEEKDAY(_xlpm.fechas,2)=1))+(D33*(WEEKDAY(_xlpm.fechas,2)=2))+(E33*(WEEKDAY(_xlpm.fechas,2)=3))+(F33*(WEEKDAY(_xlpm.fechas,2)=4))+(G33*(WEEKDAY(_xlpm.fechas,2)=5))+(H33*(WEEKDAY(_xlpm.fechas,2)=6))+(I33*(WEEKDAY(_xlpm.fechas,2)=7)),_xlpm.validas,_xlfn._xlws.FILTER(_xlpm.fechas,(_xlpm.dias>0)*((_xlpm.fechas+_xlpm.hora)>=(NOW()-TIME(0,3,0)))),_xlpm.prox,_xlfn.TAKE(_xlpm.validas,4),IF(_xlpm.activo<>"SI","Inactivo",IF(SUMPRODUCT(--C33:I33)=0,"Manual / cuando aplique",_xlfn.TEXTJOIN(CHAR(10),TRUE,_xlfn.MAP(_xlpm.prox,_xlfn.LAMBDA(_xlpm.f,CHOOSE(WEEKDAY(_xlpm.f),"domingo","lunes","martes","miércoles","jueves","viernes","sábado")&" "&TEXT(_xlpm.f,"dd")&"/"&CHOOSE(MONTH(_xlpm.f),"Ene","Feb","Mar","Abr","May","Jun","Jul","Ago","Sep","Oct","Nov","Dic")&"/"&TEXT(_xlpm.f,"yyyy")&" "&TEXT(_xlpm.hora,"hh:mm")&" hrs"))))))} -> martes 14/Jul/2026 21:00 hrs jueves 16/Jul/2026 21:00 hrs martes 21/Jul/2026 21:00 hrs jueves 23/Jul/2026 21:00 hrs | P33: Buenas noches a todos, chicos._x000D_ _x000D_ Como recordatorio, les pido que antes de dormir verifiquen que la estufa esté completamente apagada para evitar accidentes. Asimismo, favor de apagar todas las luces que no se estén utilizando._x000D_ _x000D_ Gracias por su apoyo y que tengan una excelente noche.
A34: ACME Residence 005 | B34: Ruido fin de semana | C34: FALSE | D34: FALSE | E34: FALSE | F34: FALSE | G34: FALSE | H34: TRUE | I34: FALSE | J34: 21:00 hrs | K34: SI | L34: NO | M34: PENDING | O34: {=_xlfn.LET(_xlpm.activo,K34,_xlpm.horaTxt,J34,_xlpm.base,TODAY(),_xlpm.fechas,_xlpm.base+_xlfn.SEQUENCE(180,,0),_xlpm.hora,IF(ISNUMBER(_xlpm.horaTxt),_xlpm.horaTxt,IFERROR(TIMEVALUE(SUBSTITUTE(_xlpm.horaTxt," hrs","")),TIME(9,0,0))),_xlpm.dias,(C34*(WEEKDAY(_xlpm.fechas,2)=1))+(D34*(WEEKDAY(_xlpm.fechas,2)=2))+(E34*(WEEKDAY(_xlpm.fechas,2)=3))+(F34*(WEEKDAY(_xlpm.fechas,2)=4))+(G34*(WEEKDAY(_xlpm.fechas,2)=5))+(H34*(WEEKDAY(_xlpm.fechas,2)=6))+(I34*(WEEKDAY(_xlpm.fechas,2)=7)),_xlpm.validas,_xlfn._xlws.FILTER(_xlpm.fechas,(_xlpm.dias>0)*((_xlpm.fechas+_xlpm.hora)>=(NOW()-TIME(0,3,0)))),_xlpm.prox,_xlfn.TAKE(_xlpm.validas,4),IF(_xlpm.activo<>"SI","Inactivo",IF(SUMPRODUCT(--C34:I34)=0,"Manual / cuando aplique",_xlfn.TEXTJOIN(CHAR(10),TRUE,_xlfn.MAP(_xlpm.prox,_xlfn.LAMBDA(_xlpm.f,CHOOSE(WEEKDAY(_xlpm.f),"domingo","lunes","martes","miércoles","jueves","viernes","sábado")&" "&TEXT(_xlpm.f,"dd")&"/"&CHOOSE(MONTH(_xlpm.f),"Ene","Feb","Mar","Abr","May","Jun","Jul","Ago","Sep","Oct","Nov","Dic")&"/"&TEXT(_xlpm.f,"yyyy")&" "&TEXT(_xlpm.hora,"hh:mm")&" hrs"))))))} -> sábado 11/Jul/2026 21:00 hrs sábado 18/Jul/2026 21:00 hrs sábado 25/Jul/2026 21:00 hrs sábado 01/Ago/2026 21:00 hrs | P34: Buenas noches a todos, chicos._x000D_ _x000D_ Solo como recordatorio, al ser fin de semana les pedimos de la manera más amable que moderen el ruido. Sabemos que muchos aprovechan estos días, pero también hay personas que necesitan descansar después de una semana de trabajo._x000D_ _x000D_ Seamos considerados con los demás y ayudemos a mantener un ambiente tranquilo para todos._x000D_ _x000D_ Muchas gracias por su apoyo. ¡Que tengan una excelente noche!
A35: CASA / GRUPO: ACME Residence 006
A36: ACME Residence 006 | B36: Limpieza y orden | C36: FALSE | D36: FALSE | E36: FALSE | F36: FALSE | G36: FALSE | H36: FALSE | I36: FALSE | K36: SI | L36: NO | M36: PENDING | O36: {=_xlfn.LET(_xlpm.activo,K36,_xlpm.horaTxt,J36,_xlpm.base,TODAY(),_xlpm.fechas,_xlpm.base+_xlfn.SEQUENCE(180,,0),_xlpm.hora,IF(ISNUMBER(_xlpm.horaTxt),_xlpm.horaTxt,IFERROR(TIMEVALUE(SUBSTITUTE(_xlpm.horaTxt," hrs","")),TIME(9,0,0))),_xlpm.dias,(C36*(WEEKDAY(_xlpm.fechas,2)=1))+(D36*(WEEKDAY(_xlpm.fechas,2)=2))+(E36*(WEEKDAY(_xlpm.fechas,2)=3))+(F36*(WEEKDAY(_xlpm.fechas,2)=4))+(G36*(WEEKDAY(_xlpm.fechas,2)=5))+(H36*(WEEKDAY(_xlpm.fechas,2)=6))+(I36*(WEEKDAY(_xlpm.fechas,2)=7)),_xlpm.validas,_xlfn._xlws.FILTER(_xlpm.fechas,(_xlpm.dias>0)*((_xlpm.fechas+_xlpm.hora)>=(NOW()-TIME(0,3,0)))),_xlpm.prox,_xlfn.TAKE(_xlpm.validas,4),IF(_xlpm.activo<>"SI","Inactivo",IF(SUMPRODUCT(--C36:I36)=0,"Manual / cuando aplique",_xlfn.TEXTJOIN(CHAR(10),TRUE,_xlfn.MAP(_xlpm.prox,_xlfn.LAMBDA(_xlpm.f,CHOOSE(WEEKDAY(_xlpm.f),"domingo","lunes","martes","miércoles","jueves","viernes","sábado")&" "&TEXT(_xlpm.f,"dd")&"/"&CHOOSE(MONTH(_xlpm.f),"Ene","Feb","Mar","Abr","May","Jun","Jul","Ago","Sep","Oct","Nov","Dic")&"/"&TEXT(_xlpm.f,"yyyy")&" "&TEXT(_xlpm.hora,"hh:mm")&" hrs"))))))} -> Manual / cuando aplique | P36: Buenos días chicos,_x000D_ _x000D_ Como recordatorio, les pido de su amable apoyo para:_x000D_ _x000D_ * Lavar, secar y guardar los trastes que utilicen._x000D_ * Barrer la cocina y dejarla limpia para que la siguiente persona la encuentre en las mismas condiciones._x000D_ * Apagar todas las luces que no estén utilizando._x000D_ * Colocar las sillas del comedor en su lugar después de usarlas._x000D_ _x000D_ Muchas gracias por su colaboración para mantener la casa limpia y ordenada.
A37: ACME Residence 006 | B37: Lavandería - horario | C37: TRUE | D37: FALSE | E37: FALSE | F37: TRUE | G37: FALSE | H37: FALSE | I37: FALSE | J37: 19:00 hrs | K37: SI | L37: NO | M37: PENDING | O37: {=_xlfn.LET(_xlpm.activo,K37,_xlpm.horaTxt,J37,_xlpm.base,TODAY(),_xlpm.fechas,_xlpm.base+_xlfn.SEQUENCE(180,,0),_xlpm.hora,IF(ISNUMBER(_xlpm.horaTxt),_xlpm.horaTxt,IFERROR(TIMEVALUE(SUBSTITUTE(_xlpm.horaTxt," hrs","")),TIME(9,0,0))),_xlpm.dias,(C37*(WEEKDAY(_xlpm.fechas,2)=1))+(D37*(WEEKDAY(_xlpm.fechas,2)=2))+(E37*(WEEKDAY(_xlpm.fechas,2)=3))+(F37*(WEEKDAY(_xlpm.fechas,2)=4))+(G37*(WEEKDAY(_xlpm.fechas,2)=5))+(H37*(WEEKDAY(_xlpm.fechas,2)=6))+(I37*(WEEKDAY(_xlpm.fechas,2)=7)),_xlpm.validas,_xlfn._xlws.FILTER(_xlpm.fechas,(_xlpm.dias>0)*((_xlpm.fechas+_xlpm.hora)>=(NOW()-TIME(0,3,0)))),_xlpm.prox,_xlfn.TAKE(_xlpm.validas,4),IF(_xlpm.activo<>"SI","Inactivo",IF(SUMPRODUCT(--C37:I37)=0,"Manual / cuando aplique",_xlfn.TEXTJOIN(CHAR(10),TRUE,_xlfn.MAP(_xlpm.prox,_xlfn.LAMBDA(_xlpm.f,CHOOSE(WEEKDAY(_xlpm.f),"domingo","lunes","martes","miércoles","jueves","viernes","sábado")&" "&TEXT(_xlpm.f,"dd")&"/"&CHOOSE(MONTH(_xlpm.f),"Ene","Feb","Mar","Abr","May","Jun","Jul","Ago","Sep","Oct","Nov","Dic")&"/"&TEXT(_xlpm.f,"yyyy")&" "&TEXT(_xlpm.hora,"hh:mm")&" hrs"))))))} -> lunes 13/Jul/2026 19:00 hrs jueves 16/Jul/2026 19:00 hrs lunes 20/Jul/2026 19:00 hrs jueves 23/Jul/2026 19:00 hrs | P37: Buenas tardes, chicos._x000D_ _x000D_ Solo para confirmarles que el horario de lavado ya está disponible. Pueden utilizar la lavandería de 7:00 p. m. a 10:30 p. m._x000D_ _x000D_ Gracias.
A38: ACME Residence 006 | B38: Lavandería - filtro secadora | C38: TRUE | D38: FALSE | E38: FALSE | F38: TRUE | G38: FALSE | H38: FALSE | I38: FALSE | J38: 20:00 hrs | K38: SI | L38: NO | M38: PENDING | O38: {=_xlfn.LET(_xlpm.activo,K38,_xlpm.horaTxt,J38,_xlpm.base,TODAY(),_xlpm.fechas,_xlpm.base+_xlfn.SEQUENCE(180,,0),_xlpm.hora,IF(ISNUMBER(_xlpm.horaTxt),_xlpm.horaTxt,IFERROR(TIMEVALUE(SUBSTITUTE(_xlpm.horaTxt," hrs","")),TIME(9,0,0))),_xlpm.dias,(C38*(WEEKDAY(_xlpm.fechas,2)=1))+(D38*(WEEKDAY(_xlpm.fechas,2)=2))+(E38*(WEEKDAY(_xlpm.fechas,2)=3))+(F38*(WEEKDAY(_xlpm.fechas,2)=4))+(G38*(WEEKDAY(_xlpm.fechas,2)=5))+(H38*(WEEKDAY(_xlpm.fechas,2)=6))+(I38*(WEEKDAY(_xlpm.fechas,2)=7)),_xlpm.validas,_xlfn._xlws.FILTER(_xlpm.fechas,(_xlpm.dias>0)*((_xlpm.fechas+_xlpm.hora)>=(NOW()-TIME(0,3,0)))),_xlpm.prox,_xlfn.TAKE(_xlpm.validas,4),IF(_xlpm.activo<>"SI","Inactivo",IF(SUMPRODUCT(--C38:I38)=0,"Manual / cuando aplique",_xlfn.TEXTJOIN(CHAR(10),TRUE,_xlfn.MAP(_xlpm.prox,_xlfn.LAMBDA(_xlpm.f,CHOOSE(WEEKDAY(_xlpm.f),"domingo","lunes","martes","miércoles","jueves","viernes","sábado")&" "&TEXT(_xlpm.f,"dd")&"/"&CHOOSE(MONTH(_xlpm.f),"Ene","Feb","Mar","Abr","May","Jun","Jul","Ago","Sep","Oct","Nov","Dic")&"/"&TEXT(_xlpm.f,"yyyy")&" "&TEXT(_xlpm.hora,"hh:mm")&" hrs"))))))} -> lunes 13/Jul/2026 20:00 hrs jueves 16/Jul/2026 20:00 hrs lunes 20/Jul/2026 20:00 hrs jueves 23/Jul/2026 20:00 hrs | P38: Como recordatorio, les pido que después de utilizar la secadora limpien el filtro. Es importante cuidarla para mantenerla en buen funcionamiento y evitar daños._x000D_ _x000D_ Gracias por su apoyo.
A39: ACME Residence 006 | B39: Estufa y luces | C39: FALSE | D39: TRUE | E39: FALSE | F39: TRUE | G39: FALSE | H39: FALSE | I39: FALSE | J39: 21:00 hrs | K39: SI | L39: NO | M39: PENDING | O39: {=_xlfn.LET(_xlpm.activo,K39,_xlpm.horaTxt,J39,_xlpm.base,TODAY(),_xlpm.fechas,_xlpm.base+_xlfn.SEQUENCE(180,,0),_xlpm.hora,IF(ISNUMBER(_xlpm.horaTxt),_xlpm.horaTxt,IFERROR(TIMEVALUE(SUBSTITUTE(_xlpm.horaTxt," hrs","")),TIME(9,0,0))),_xlpm.dias,(C39*(WEEKDAY(_xlpm.fechas,2)=1))+(D39*(WEEKDAY(_xlpm.fechas,2)=2))+(E39*(WEEKDAY(_xlpm.fechas,2)=3))+(F39*(WEEKDAY(_xlpm.fechas,2)=4))+(G39*(WEEKDAY(_xlpm.fechas,2)=5))+(H39*(WEEKDAY(_xlpm.fechas,2)=6))+(I39*(WEEKDAY(_xlpm.fechas,2)=7)),_xlpm.validas,_xlfn._xlws.FILTER(_xlpm.fechas,(_xlpm.dias>0)*((_xlpm.fechas+_xlpm.hora)>=(NOW()-TIME(0,3,0)))),_xlpm.prox,_xlfn.TAKE(_xlpm.validas,4),IF(_xlpm.activo<>"SI","Inactivo",IF(SUMPRODUCT(--C39:I39)=0,"Manual / cuando aplique",_xlfn.TEXTJOIN(CHAR(10),TRUE,_xlfn.MAP(_xlpm.prox,_xlfn.LAMBDA(_xlpm.f,CHOOSE(WEEKDAY(_xlpm.f),"domingo","lunes","martes","miércoles","jueves","viernes","sábado")&" "&TEXT(_xlpm.f,"dd")&"/"&CHOOSE(MONTH(_xlpm.f),"Ene","Feb","Mar","Abr","May","Jun","Jul","Ago","Sep","Oct","Nov","Dic")&"/"&TEXT(_xlpm.f,"yyyy")&" "&TEXT(_xlpm.hora,"hh:mm")&" hrs"))))))} -> martes 14/Jul/2026 21:00 hrs jueves 16/Jul/2026 21:00 hrs martes 21/Jul/2026 21:00 hrs jueves 23/Jul/2026 21:00 hrs | P39: Buenas noches a todos, chicos._x000D_ _x000D_ Como recordatorio, les pido que antes de dormir verifiquen que la estufa esté completamente apagada para evitar accidentes. Asimismo, favor de apagar todas las luces que no se estén utilizando._x000D_ _x000D_ Gracias por su apoyo y que tengan una excelente noche.
A40: ACME Residence 006 | B40: Ruido fin de semana | C40: FALSE | D40: FALSE | E40: FALSE | F40: FALSE | G40: FALSE | H40: TRUE | I40: FALSE | J40: 21:00 hrs | K40: SI | L40: NO | M40: PENDING | O40: {=_xlfn.LET(_xlpm.activo,K40,_xlpm.horaTxt,J40,_xlpm.base,TODAY(),_xlpm.fechas,_xlpm.base+_xlfn.SEQUENCE(180,,0),_xlpm.hora,IF(ISNUMBER(_xlpm.horaTxt),_xlpm.horaTxt,IFERROR(TIMEVALUE(SUBSTITUTE(_xlpm.horaTxt," hrs","")),TIME(9,0,0))),_xlpm.dias,(C40*(WEEKDAY(_xlpm.fechas,2)=1))+(D40*(WEEKDAY(_xlpm.fechas,2)=2))+(E40*(WEEKDAY(_xlpm.fechas,2)=3))+(F40*(WEEKDAY(_xlpm.fechas,2)=4))+(G40*(WEEKDAY(_xlpm.fechas,2)=5))+(H40*(WEEKDAY(_xlpm.fechas,2)=6))+(I40*(WEEKDAY(_xlpm.fechas,2)=7)),_xlpm.validas,_xlfn._xlws.FILTER(_xlpm.fechas,(_xlpm.dias>0)*((_xlpm.fechas+_xlpm.hora)>=(NOW()-TIME(0,3,0)))),_xlpm.prox,_xlfn.TAKE(_xlpm.validas,4),IF(_xlpm.activo<>"SI","Inactivo",IF(SUMPRODUCT(--C40:I40)=0,"Manual / cuando aplique",_xlfn.TEXTJOIN(CHAR(10),TRUE,_xlfn.MAP(_xlpm.prox,_xlfn.LAMBDA(_xlpm.f,CHOOSE(WEEKDAY(_xlpm.f),"domingo","lunes","martes","miércoles","jueves","viernes","sábado")&" "&TEXT(_xlpm.f,"dd")&"/"&CHOOSE(MONTH(_xlpm.f),"Ene","Feb","Mar","Abr","May","Jun","Jul","Ago","Sep","Oct","Nov","Dic")&"/"&TEXT(_xlpm.f,"yyyy")&" "&TEXT(_xlpm.hora,"hh:mm")&" hrs"))))))} -> sábado 11/Jul/2026 21:00 hrs sábado 18/Jul/2026 21:00 hrs sábado 25/Jul/2026 21:00 hrs sábado 01/Ago/2026 21:00 hrs | P40: Buenas noches a todos, chicos._x000D_ _x000D_ Solo como recordatorio, al ser fin de semana les pedimos de la manera más amable que moderen el ruido. Sabemos que muchos aprovechan estos días, pero también hay personas que necesitan descansar después de una semana de trabajo._x000D_ _x000D_ Seamos considerados con los demás y ayudemos a mantener un ambiente tranquilo para todos._x000D_ _x000D_ Muchas gracias por su apoyo. ¡Que tengan una excelente noche!
A41: CASA / GRUPO: ACME Residence 007
...

Sheet Resumen
A1: Resumen visual por casa
A3: Casa / Grupo | B3: Total | C3: Pendientes | D3: Enviados | E3: Errores | F3: Activos | G3: Manuales SI | H3: Última nota
A4: Departamento 510 | B4: =COUNTIF('Recordatorios Programados'!A:A,A4) -> 0 | C4: =COUNTIFS('Recordatorios Programados'!A:A,A4,'Recordatorios Programados'!G:G,"PENDIENTE") -> 0 | D4: =COUNTIFS('Recordatorios Programados'!A:A,A4,'Recordatorios Programados'!G:G,"ENVIADO") -> 0 | E4: =COUNTIFS('Recordatorios Programados'!A:A,A4,'Recordatorios Programados'!G:G,"ERROR") -> 0 | F4: =COUNTIFS('Recordatorios Programados'!A:A,A4,'Recordatorios Programados'!E:E,"SI") -> 0 | G4: =COUNTIFS('Recordatorios Programados'!A:A,A4,'Recordatorios Programados'!F:F,"SI") -> 0
A5: Basement 78 Sutherland | B5: =COUNTIF('Recordatorios Programados'!A:A,A5) -> 0 | C5: =COUNTIFS('Recordatorios Programados'!A:A,A5,'Recordatorios Programados'!G:G,"PENDIENTE") -> 0 | D5: =COUNTIFS('Recordatorios Programados'!A:A,A5,'Recordatorios Programados'!G:G,"ENVIADO") -> 0 | E5: =COUNTIFS('Recordatorios Programados'!A:A,A5,'Recordatorios Programados'!G:G,"ERROR") -> 0 | F5: =COUNTIFS('Recordatorios Programados'!A:A,A5,'Recordatorios Programados'!E:E,"SI") -> 0 | G5: =COUNTIFS('Recordatorios Programados'!A:A,A5,'Recordatorios Programados'!F:F,"SI") -> 0
A6: 11 Huntingwood | B6: =COUNTIF('Recordatorios Programados'!A:A,A6) -> 0 | C6: =COUNTIFS('Recordatorios Programados'!A:A,A6,'Recordatorios Programados'!G:G,"PENDIENTE") -> 0 | D6: =COUNTIFS('Recordatorios Programados'!A:A,A6,'Recordatorios Programados'!G:G,"ENVIADO") -> 0 | E6: =COUNTIFS('Recordatorios Programados'!A:A,A6,'Recordatorios Programados'!G:G,"ERROR") -> 0 | F6: =COUNTIFS('Recordatorios Programados'!A:A,A6,'Recordatorios Programados'!E:E,"SI") -> 0 | G6: =COUNTIFS('Recordatorios Programados'!A:A,A6,'Recordatorios Programados'!F:F,"SI") -> 0
A7: 14 Hayden Crt Brampton | B7: =COUNTIF('Recordatorios Programados'!A:A,A7) -> 0 | C7: =COUNTIFS('Recordatorios Programados'!A:A,A7,'Recordatorios Programados'!G:G,"PENDIENTE") -> 0 | D7: =COUNTIFS('Recordatorios Programados'!A:A,A7,'Recordatorios Programados'!G:G,"ENVIADO") -> 0 | E7: =COUNTIFS('Recordatorios Programados'!A:A,A7,'Recordatorios Programados'!G:G,"ERROR") -> 0 | F7: =COUNTIFS('Recordatorios Programados'!A:A,A7,'Recordatorios Programados'!E:E,"SI") -> 0 | G7: =COUNTIFS('Recordatorios Programados'!A:A,A7,'Recordatorios Programados'!F:F,"SI") -> 0
A8: 9 Sutherland Ave Brampton ON L6V 2H3 Canada | B8: =COUNTIF('Recordatorios Programados'!A:A,A8) -> 0 | C8: =COUNTIFS('Recordatorios Programados'!A:A,A8,'Recordatorios Programados'!G:G,"PENDIENTE") -> 0 | D8: =COUNTIFS('Recordatorios Programados'!A:A,A8,'Recordatorios Programados'!G:G,"ENVIADO") -> 0 | E8: =COUNTIFS('Recordatorios Programados'!A:A,A8,'Recordatorios Programados'!G:G,"ERROR") -> 0 | F8: =COUNTIFS('Recordatorios Programados'!A:A,A8,'Recordatorios Programados'!E:E,"SI") -> 0 | G8: =COUNTIFS('Recordatorios Programados'!A:A,A8,'Recordatorios Programados'!F:F,"SI") -> 0
A9: 116 Madoc | B9: =COUNTIF('Recordatorios Programados'!A:A,A9) -> 0 | C9: =COUNTIFS('Recordatorios Programados'!A:A,A9,'Recordatorios Programados'!G:G,"PENDIENTE") -> 0 | D9: =COUNTIFS('Recordatorios Programados'!A:A,A9,'Recordatorios Programados'!G:G,"ENVIADO") -> 0 | E9: =COUNTIFS('Recordatorios Programados'!A:A,A9,'Recordatorios Programados'!G:G,"ERROR") -> 0 | F9: =COUNTIFS('Recordatorios Programados'!A:A,A9,'Recordatorios Programados'!E:E,"SI") -> 0 | G9: =COUNTIFS('Recordatorios Programados'!A:A,A9,'Recordatorios Programados'!F:F,"SI") -> 0
A10: HOME 185 VODDEN ST E | B10: =COUNTIF('Recordatorios Programados'!A:A,A10) -> 0 | C10: =COUNTIFS('Recordatorios Programados'!A:A,A10,'Recordatorios Programados'!G:G,"PENDIENTE") -> 0 | D10: =COUNTIFS('Recordatorios Programados'!A:A,A10,'Recordatorios Programados'!G:G,"ENVIADO") -> 0 | E10: =COUNTIFS('Recordatorios Programados'!A:A,A10,'Recordatorios Programados'!G:G,"ERROR") -> 0 | F10: =COUNTIFS('Recordatorios Programados'!A:A,A10,'Recordatorios Programados'!E:E,"SI") -> 0 | G10: =COUNTIFS('Recordatorios Programados'!A:A,A10,'Recordatorios Programados'!F:F,"SI") -> 0
A11: 96 Sutherland | B11: =COUNTIF('Recordatorios Programados'!A:A,A11) -> 0 | C11: =COUNTIFS('Recordatorios Programados'!A:A,A11,'Recordatorios Programados'!G:G,"PENDIENTE") -> 0 | D11: =COUNTIFS('Recordatorios Programados'!A:A,A11,'Recordatorios Programados'!G:G,"ENVIADO") -> 0 | E11: =COUNTIFS('Recordatorios Programados'!A:A,A11,'Recordatorios Programados'!G:G,"ERROR") -> 0 | F11: =COUNTIFS('Recordatorios Programados'!A:A,A11,'Recordatorios Programados'!E:E,"SI") -> 0 | G11: =COUNTIFS('Recordatorios Programados'!A:A,A11,'Recordatorios Programados'!F:F,"SI") -> 0
A12: Departamento 303 | B12: =COUNTIF('Recordatorios Programados'!A:A,A12) -> 0 | C12: =COUNTIFS('Recordatorios Programados'!A:A,A12,'Recordatorios Programados'!G:G,"PENDIENTE") -> 0 | D12: =COUNTIFS('Recordatorios Programados'!A:A,A12,'Recordatorios Programados'!G:G,"ENVIADO") -> 0 | E12: =COUNTIFS('Recordatorios Programados'!A:A,A12,'Recordatorios Programados'!G:G,"ERROR") -> 0 | F12: =COUNTIFS('Recordatorios Programados'!A:A,A12,'Recordatorios Programados'!E:E,"SI") -> 0 | G12: =COUNTIFS('Recordatorios Programados'!A:A,A12,'Recordatorios Programados'!F:F,"SI") -> 0
A13: 45 Hansen Rd N #99 | B13: =COUNTIF('Recordatorios Programados'!A:A,A13) -> 0 | C13: =COUNTIFS('Recordatorios Programados'!A:A,A13,'Recordatorios Programados'!G:G,"PENDIENTE") -> 0 | D13: =COUNTIFS('Recordatorios Programados'!A:A,A13,'Recordatorios Programados'!G:G,"ENVIADO") -> 0 | E13: =COUNTIFS('Recordatorios Programados'!A:A,A13,'Recordatorios Programados'!G:G,"ERROR") -> 0 | F13: =COUNTIFS('Recordatorios Programados'!A:A,A13,'Recordatorios Programados'!E:E,"SI") -> 0 | G13: =COUNTIFS('Recordatorios Programados'!A:A,A13,'Recordatorios Programados'!F:F,"SI") -> 0
A14: 17 Hilldowntree | B14: =COUNTIF('Recordatorios Programados'!A:A,A14) -> 0 | C14: =COUNTIFS('Recordatorios Programados'!A:A,A14,'Recordatorios Programados'!G:G,"PENDIENTE") -> 0 | D14: =COUNTIFS('Recordatorios Programados'!A:A,A14,'Recordatorios Programados'!G:G,"ENVIADO") -> 0 | E14: =COUNTIFS('Recordatorios Programados'!A:A,A14,'Recordatorios Programados'!G:G,"ERROR") -> 0 | F14: =COUNTIFS('Recordatorios Programados'!A:A,A14,'Recordatorios Programados'!E:E,"SI") -> 0 | G14: =COUNTIFS('Recordatorios Programados'!A:A,A14,'Recordatorios Programados'!F:F,"SI") -> 0
A15: 26 Lincoln Brampton | B15: =COUNTIF('Recordatorios Programados'!A:A,A15) -> 0 | C15: =COUNTIFS('Recordatorios Programados'!A:A,A15,'Recordatorios Programados'!G:G,"PENDIENTE") -> 0 | D15: =COUNTIFS('Recordatorios Programados'!A:A,A15,'Recordatorios Programados'!G:G,"ENVIADO") -> 0 | E15: =COUNTIFS('Recordatorios Programados'!A:A,A15,'Recordatorios Programados'!G:G,"ERROR") -> 0 | F15: =COUNTIFS('Recordatorios Programados'!A:A,A15,'Recordatorios Programados'!E:E,"SI") -> 0 | G15: =COUNTIFS('Recordatorios Programados'!A:A,A15,'Recordatorios Programados'!F:F,"SI") -> 0
A16: 152 Royal Palm | B16: =COUNTIF('Recordatorios Programados'!A:A,A16) -> 0 | C16: =COUNTIFS('Recordatorios Programados'!A:A,A16,'Recordatorios Programados'!G:G,"PENDIENTE") -> 0 | D16: =COUNTIFS('Recordatorios Programados'!A:A,A16,'Recordatorios Programados'!G:G,"ENVIADO") -> 0 | E16: =COUNTIFS('Recordatorios Programados'!A:A,A16,'Recordatorios Programados'!G:G,"ERROR") -> 0 | F16: =COUNTIFS('Recordatorios Programados'!A:A,A16,'Recordatorios Programados'!E:E,"SI") -> 0 | G16: =COUNTIFS('Recordatorios Programados'!A:A,A16,'Recordatorios Programados'!F:F,"SI") -> 0

Sheet Mensajes Base
A1: Mensajes base
A3: Categoría | B3: Programación | C3: Hora | D3: Activo por defecto | E3: Mensaje
